Workbook
Name A: #REF!
Name A: #REF!
Name A: #REF!
Name ActualNumberOfPayments: IFERROR(IF(LoanIsGood,IF(PaymentsPerYear=1,1,MATCH(0.01,Mortgage!End_Bal,-1)+1)),"")
Name B: #REF!
Name B: #REF!
Name B: #REF!
Name Beg_Bal: #REF!
Name Beg_Bal: #REF!
Name Beg_Bal: #REF!
Name Categories: OFFSET('[1]Archived Categories Sheet'!$J$7,0,0,COUNTIF('[1]Archived Categories Sheet'!$J$7:$J$44,"<>"&"--"),1)
Name CategoryIdentifiers: #REF!
Name CategoryNames: Monthly!$C$9:$C$193
Name ColumnTitle1: PaymentSchedule[[#Headers],[PMT NO]]
Name Data: #REF!
Name Data: #REF!
Name Data: #REF!
Name ddf: #REF!
Name eb: #REF!
Name eb: #REF!
Name eb: #REF!
Name End_Bal: PaymentSchedule[ENDING BALANCE]
Name End_Bal: #REF!
Name End_Bal: #REF!
Name End_Bal: #REF!
Name ep: #REF!
Name ep: #REF!
Name ep: #REF!
Name Extra_Pay: #REF!
Name Extra_Pay: #REF!
Name Extra_Pay: #REF!
Name ExtraPayments: Mortgage!$E$8
Name ff: #REF!
Name Full_Print: #REF!
Name Full_Print: #REF!
Name Full_Print: #REF!
Name h: IF([2]Fixed!Values_Entered,[2]Fixed!Header_Row+[2]Fixed!Number_of_Payments,[2]Fixed!Header_Row)
Name h: IF([2]Fixed!Values_Entered,[2]Fixed!Header_Row+[2]Fixed!Number_of_Payments,[2]Fixed!Header_Row)
Name h: IF([2]Fixed!Values_Entered,[2]Fixed!Header_Row+[2]Fixed!Number_of_Payments,[2]Fixed!Header_Row)
Name Header_Row: ROW(#REF!)
Name Header_Row: ROW(#REF!)
Name Header_Row: ROW(#REF!)
Name HiddenCategoriesCategoryNames: _xlfn.ANCHORARRAY([1]HiddenCategories!$B$2)
Name Int: #REF!
Name Int: #REF!
Name Int: #REF!
Name Interest_Rate: #REF!
Name Interest_Rate: #REF!
Name Interest_Rate: #REF!
Name InterestRate: Mortgage!$E$3
Name Last_Row: #N/A
Name Last_Row: #N/A
Name LastCol: MATCH(REPT("z",255),Mortgage!$10:$10)
Name LastRow: MATCH(9.99E+307,Mortgage!$B:$B)
Name LenderName: Mortgage!$H$8:$I$8
Name Loan_Amount: #REF!
Name Loan_Amount: #REF!
Name Loan_Amount: #REF!
Name Loan_Start: #REF!
Name Loan_Start: #REF!

Sheet FinSnapshot
A8: Category | B8: Dec'02 | C8: Dec '03 | D8: Dec'04 | E8: Dec'05 | F8: Dec'06 | G8: Dec'07 | H8: Dec'08 | I8: Dec'09 | J8: Dec '10 | K8: Dec'11 | L8: Dec'12 | M8: Dec'13 | N8: Dec'14 | O8: Dec'15 | P8: Dec'16 | Q8: Dec'17 | R8: Dec'18 | S8: Dec'19 | T8: Dec'20 | U8: Dec'21 | V8: Dec'22 | W8: Dec'23 | X8: Dec'24 | Y8: DDec'25 | Z8: Dec'19 | AA8: Dec'20 | AB8: Dec'30 | AC8: Comp NE'15 | AD8: Decade | AE8: Yrly Avg/Dec
A9: Year | B9: 1 | C9: 2 | D9: 3 | E9: 4 | F9: 5 | G9: 6 | H9: 7 | I9: 8 | J9: 9 | K9: 10 | L9: 11 | M9: 12 | N9: 13 | O9: 14 | P9: 15 | Q9: 16 | R9: 17 | S9: 18 | T9: 19 | U9: 20 | V9: 21 | W9: 22 | X9: 23 | Z9: 18 | AA9: 18 | AB9: 30
A10: Cash Assets | B10: =SUM(B11:B12) -> 33800 | C10: =SUM(C11:C12) -> 46727 | D10: =SUM(D11:D12) -> 51927 | E10: =SUM(E11:E12) -> 48000 | F10: =SUM(F11:F12) -> 61000 | G10: =SUM(G11:G12) -> 90551 | H10: =SUM(H11:H12) -> 90898 | I10: =SUM(I11:I12) -> 155500 | ... X10: =SUM(X11:X12) -> 510000 | Z10: =SUM(Z11:Z12) -> 1016000 | AA10: =SUM(AA11:AA12) -> 115000 | AB10: =SUM(AB11:AB12) -> 355000 | AC10: =(R10-O10)/O10 -> 3.375 | AD10: =(Z10-I10)/I10 -> 5.5337621 | AE10: =(Z10-I10)/10 -> 86050
A11: Savings | B11: 32800 | C11: 45727 | D11: 50927 | E11: 47000 | F11: 60000 | G11: 89551 | H11: 89898 | I11: 153000 | J11: 136163 | K11: 132700 | L11: 80000 | M11: 92353 | N11: 162000 | O11: 195000 | P11: 499000 | Q11: 730000 | R11: 860000 | S11: =205282 + 121225 + 358493 + 30000 + 86000 + 200000 -> 1001000 | T11: 300500 | U11: 340000 | V11: 334000 | W11: =347000 -> 347000 | X11: 400000 | Z11: =205282 + 121225 + 358493 + 30000 + 86000 + 200000 -> 1001000 | AA11: 100000 | AB11: 340000 | AD11: =(Z11-I11)/I11 -> 5.5424837 | AE11: =(Z11-I11)/10 -> 84800
A12: Checking | B12: 1000 | C12: 1000 | D12: 1000 | E12: 1000 | F12: 1000 | G12: 1000 | H12: 1000 | I12: 2500 | J12: 3540 | K12: 3500 | L12: 3500 | M12: 20000 | N12: 20000 | O12: 5000 | P12: 35280 | Q12: 15000 | R12: 15000 | S12: 15000 | T12: 58000 | U12: 120000 | V12: 90000 | W12: 80000 | X12: 110000 | Z12: 15000 | AA12: 15000 | AB12: 15000 | AD12: =(Z12-I12)/I12 -> 5 | AE12: =(Z12-I12)/10 -> 1250
A13: Investment Accounts | B13: =SUM(B14:B20) -> 0 | C13: =SUM(C14:C20) -> 11900 | D13: =SUM(D14:D20) -> 22700 | E13: =SUM(E14:E20) -> 47268 | F13: =SUM(F14:F20) -> 89280 | G13: =SUM(G14:G20) -> 137032 | H13: =SUM(H14:H20) -> 111608 | I13: =SUM(I14:I20) -> 132750 | ... X13: =SUM(X14:X20) -> 2621522.8 | Z13: =SUM(Z14:Z20) -> 1034727 | AA13: =SUM(AA14:AA20) -> 1187900 | AB13: =SUM(AB14:AB20) -> 1562355 | AC13: =(R13-O13)/O13 -> 0.16880696 | AD13: =(Z13-I13)/I13 -> 6.7945537 | AE13: =(Z13-I13)/10 -> 90197.7
A14: SPP/SOP - S | B14: 0 | C14: 8000 | D14: 19000 | E14: 33268 | F14: 56938 | G14: 87551 | H14: 51586 | I14: 61900 | J14: 90000 | K14: 100285 | L14: 130793 | M14: 145234 | N14: 170609 | O14: 135000 | P14: 15666 | Q14: 20000 | R14: 0 | S14: 8400 | T14: 0 | U14: 65000 | V14: 0 | W14: 379429.03 | X14: 504000 | Z14: 8400 | AA14: 0 | AB14: 0 | AD14: =(Z14-I14)/I14 -> -0.86429725 | AE14: =(Z14-I14)/10 -> -5350 | AT14: SRP
A15: SPP/SOP - R | B15: 0 | C15: 1500 | D15: 1500 | E15: 1000 | F15: 3300 | G15: 7000 | H15: 265 | I15: 0 | J15: 12000 | K15: 21282 | L15: 35612 | M15: 41349 | N15: 58751 | O15: 38000 | P15: 1241 | Q15: 1500 | R15: 0 | S15: 0 | T15: 0 | U15: 0 | V15: 0 | W15: 668707.07 | X15: 310849.01 | Z15: 0 | AA15: 0 | AB15: 0 | AC15: 0 | AD15: - | AE15: =(Z15-I15)/10 -> 0 | AU15: SRP
A16: Vanguard | B16: 0 | C16: 0 | D16: 0 | E16: 10800 | F16: 25800 | G16: 39150 | H16: 52000 | I16: 62000 | J16: 120000 | K16: 158586 | L16: 201000 | M16: 284057 | N16: 327669 | O16: 375595 | P16: 439873 | Q16: 536436 | R16: 536436 | S16: 656355 | T16: 720112 | U16: 862000 | V16: 531529 | W16: 861860.61 | X16: 1015673.6 | Z16: 656355 | AA16: 862000 | AB16: 656355 | AD16: =(Z16-I16)/I16 -> 9.586371 | AE16: =(Z16-I16)/10 -> 59435.5 | AJ16: 1015673.6 | AU16: 401K
A17: Fidelity | B17: 0 | C17: 0 | D17: 0 | E17: 0 | F17: 0 | G17: 0 | H17: 0 | I17: 0 | J17: 5400 | K17: 5200 | L17: 6000 | M17: 7429 | N17: 7822 | O17: 7158 | P17: 8418 | Q17: 8922 | R17: 7500 | S17: 9072 | T17: 17700 | U17: 0 | V17: 7500 | W17: 700 | X17: 900 | Z17: 9072 | AA17: 0 | AB17: 0 | AC17: 0 | AD17: - | AE17: =(Z17-I17)/10 -> 907.2
A18: Funds/Stocks | B18: 0 | C18: 2400 | D18: 2200 | E18: 2200 | F18: 2200 | G18: 2281 | H18: 1700 | I18: 2050 | J18: 1900 | K18: 1950 | L18: 2000 | M18: 3194 | N18: 0 | O18: 0 | P18: 27513 | Q18: 30000 | R18: 35000 | S18: 35000 | T18: 42862 | U18: 48000 | V18: 45000 | W18: 48000 | X18: 78000 | Z18: 35000 | AA18: 0 | AB18: 447000 | AC18: 0 | AD18: =(Z18-I18)/I18 -> 16.073171 | AE18: =(Z18-I18)/10 -> 3295 | AU18: EMC | AV18: 12407.78
A19: 529 Plan | B19: 0 | C19: 0 | D19: 0 | E19: 0 | F19: 0 | G19: 0 | H19: 0 | I19: 400 | J19: 6400 | K19: 22000 | L19: 40000 | M19: =18714 + 52331 + 219 -> 71264 | N19: =36533 + 63300 + 239 -> 100072 | O19: 119513 | P19: 151516 | Q19: 209680 | R19: 214500 | S19: =159400 + 137000 -> 296400 | T19: =189400 + 161400 -> 350800 | U19: =227000 + 192000 -> 419000 | V19: 415000 | W19: =227100.18 + 191000 -> 418100.18 | X19: =221100.18 + 266000 -> 487100.18 | Z19: =159400 + 137000 -> 296400 | AA19: =159400 + 137000 -> 296400 | AB19: =227000 + 192000 -> 419000 | AD19: =(Z19-I19)/I19 -> 740 | AE19: =(Z19-I19)/10 -> 29600 | AU19: Scality | AV19: 6522.14
A20: T-Bills/Bonds | B20: 0 | C20: 0 | D20: 0 | E20: 0 | F20: 1042 | G20: 1050 | H20: 6057 | I20: 6400 | J20: 6400 | K20: 11672 | L20: 21672 | M20: =L20 -> 21672 | N20: 23068 | O20: 23313 | P20: 23642 | Q20: 23168 | R20: 23068 | S20: 29500 | T20: 30000 | U20: 40000 | V20: 63068 | W20: 215000 | X20: 225000 | Z20: 29500 | AA20: 29500 | AB20: 40000 | AD20: =(Z20-I20)/I20 -> 3.609375 | AE20: =(Z20-I20)/10 -> 2310
A21: Retirement Accounts | B21: =SUM(B22:B25) -> 1000 | C21: =SUM(C22:C25) -> 10300 | D21: =SUM(D22:D25) -> 26300 | E21: =SUM(E22:E25) -> 44554 | F21: =SUM(F22:F25) -> 73236 | G21: =SUM(G22:G25) -> 87000 | H21: =SUM(H22:H25) -> 70000 | I21: =SUM(I22:I25) -> 151000 | ... X21: =SUM(X22:X25) -> 1297920 | Z21: =SUM(Z22:Z25) -> 1285208 | AA21: =SUM(AA22:AA25) -> 1285208 | AB21: =SUM(AB22:AB25) -> 1581500 | AC21: =(R21-O21)/O21 -> 0.65464153 | AD21: =(Z21-I21)/I21 -> 7.5113113 | AE21: =(Z21-I21)/10 -> 113420.8 | AU21: After Tax
A22: 401K -R | B22: 0 | C22: 6800 | D22: 16000 | E22: 25000 | F22: 39452 | G22: 43000 | H22: 35000 | I22: 76000 | J22: 115000 | K22: 124165 | L22: 167229 | M22: 238869 | N22: 274827 | O22: 309828 | P22: 386453 | Q22: 446484 | R22: 16900 | S22: 42500 | T22: 76700 | U22: 115000 | V22: 142500 | W22: 167712.87 | X22: 220000 | Z22: 42500 | AA22: 42500 | AB22: 42500 | AD22: =(Z22-I22)/I22 -> -0.44078947 | AE22: =(Z22-I22)/10 -> -3350 | AU22: EMC | AV22: 5592
A23: 401K -S | B23: 1000 | C23: 3500 | D23: 10300 | E23: 19554 | F23: 33784 | G23: 44000 | H23: 35000 | I23: 75000 | J23: 112000 | K23: 122199 | L23: 163784 | M23: 236528 | N23: 276020 | O23: 316000 | P23: 386301 | Q23: 483000 | R23: 31600 | S23: =7800 + 63168 -> 70968 | T23: 122568 | U23: 199000 | V23: 199000 | W23: 280806.68 | X23: 391000 | Z23: =7800 + 63168 -> 70968 | AA23: =7800 + 63168 -> 70968 | AB23: 199000 | AD23: =(Z23-I23)/I23 -> -0.05376 | AE23: =(Z23-I23)/10 -> -403.2 | AU23: Scality
A24: Trad + Roth IRA - R | B24: 0 | C24: 0 | D24: 0 | E24: 0 | F24: 0 | G24: 0 | H24: 0 | I24: 0 | J24: 0 | K24: 0 | L24: 0 | M24: 0 | N24: 0 | O24: 0 | P24: 16119 | Q24: 83292 | R24: 503521 | S24: =507340 + 96400 -> 603740 | T24: 676000 | U24: =639000 + 133000 -> 772000 | V24: =639000 + 133000 -> 772000 | W24: =583729.6 + 132965.26 -> 716694.86 | X24: 633910 | Z24: =507340 + 96400 -> 603740 | AA24: =507340 + 96400 -> 603740 | AB24: =639000 + 133000 -> 772000 | AD24: - | AE24: =(Z24-I24)/10 -> 60374
A25: Trad + Roth IRA -S | B25: 0 | C25: 0 | D25: 0 | E25: 0 | F25: 0 | G25: 0 | H25: 0 | I25: 0 | J25: 0 | K25: 0 | L25: 0 | M25: 0 | N25: 0 | O25: 0 | P25: 23353 | Q25: 33758 | R25: 483500 | S25: =537000 + 31000 -> 568000 | T25: =585500 + 37700 -> 623200 | U25: 45000 | V25: =537000 + 31000 -> 568000 | W25: 44180.53 | X25: 53010 | Z25: =537000 + 31000 -> 568000 | AA25: =537000 + 31000 -> 568000 | AB25: =537000 + 31000 -> 568000 | AD25: - | AE25: =(Z25-I25)/10 -> 56800 | AV25: =SUM(AV19:AV24) -> 12114.14
A26: Net Worth | B26: =B28-B29 -> -2700 | C26: =C28-C29 -> 38927 | D26: =D28-D29 -> 96627 | E26: =E28-E29 -> 139210 | F26: =F28-F29 -> 223516 | G26: =G28-G29 -> 301083 | H26: =H28-H29 -> 272506 | I26: =I28-I29 -> 421750 | ... X26: =X28-X29 -> 4399442.8 | Z26: =Z28-Z29 -> 3325935 | AA26: =AA28-AA29 -> 2578108 | AB26: =AB28-AB29 -> 3488855 | AC26: =(R26-O26)/O26 -> 0.78070883 | AD26: =(Z26-I26)/I26 -> 6.8860344 | AE26: =(Z26-I26)/10 -> 290418.5
A27: NR Assets | B27: =B10+ B13 -> 33800 | C27: =C10+C13 -> 58627 | D27: =D10+D13 -> 74627 | E27: =E10 + E13 -> 95268 | F27: =F10 + F13 -> 150280 | G27: =G10 + G13 -> 227583 | H27: =H10 + H13 -> 202506 | I27: =I10+ I13 -> 288250 | J27: =J10+J13 -> 381803 | K27: =K10+K13 -> 457175 | L27: =L10 + L13 -> 520577 | M27: =M10 + M13 -> 686552 | N27: =N10 + N13 -> 869991 | O27: =O10 + O13 -> 898579 | P27: =P10 + P13 -> 1202149 | Q27: =Q10 + Q13 -> 1574706 | R27: =R10 + R13 -> 1691504 | S27: =S10 + S13 -> 2050727 | ... X27: =X10 + X13 -> 3131522.8 | Z27: =Z10 + Z13 -> 2050727 | AA27: =AA10 + AA13 -> 1302900 | AB27: =AB10 + AB13 -> 1917355 | AD27: =(Z27-I27)/I27 -> 6.1144042 | AE27: =(Z27-I27)/10 -> 176247.7
A28: Net Assets | B28: =B10+B21+B13 -> 34800 | C28: =C10+C21+C13 -> 68927 | D28: =D10+D21+D13 -> 100927 | E28: =E10+E21+E13 -> 139822 | F28: =F10+F21+F13 -> 223516 | G28: =G10+G21+G13 -> 314583 | H28: =H10+H21+H13 -> 272506 | I28: =I10+I21+I13 -> 439250 | ... X28: =X10+X21+X13 -> 4429442.8 | Z28: =Z10+Z21+Z13 -> 3335935 | AA28: =AA10+AA21+AA13 -> 2588108 | AB28: =AB10+AB21+AB13 -> 3498855 | AD28: =(Z28-I28)/I28 -> 6.5946158 | AE28: =(Z28-I28)/10 -> 289668.5
A29: Debt | B29: 37500 | C29: 30000 | D29: 4300 | E29: 612 | F29: 0 | G29: 13500 | H29: 0 | I29: 17500 | J29: 17500 | K29: 12500 | L29: 0 | M29: 0 | N29: 0 | O29: 0 | P29: 9209 | Q29: 10900 | R29: 12500 | S29: 10900 | T29: 15000 | U29: 11000 | V29: 10900 | W29: 60000 | X29: 30000 | Z29: 10000 | AA29: 10000 | AB29: 10000 | AD29: =(Z29-I29)/I29 -> -0.42857143 | AE29: -
A30: Home
A31: Home Ownership | B31: 0 | C31: 0 | D31: 0.010230918 | E31: 0.040341832 | F31: 0.073463644 | G31: 0.1173 | H31: 0.063926789 | I31: -0.14693035 | J31: 0 | K31: -0.096293153 | L31: -0.068697073 | M31: 0.010600279 | N31: 0.010600279 | O31: 0.010600279 | P31: 0 | Q31: 0 | R31: 0 | S31: =S32/300500 -> 0 | T31: =T34/3267379 -> 0.72584448 | U31: =U34/3267379 -> 0.71059097 | V31: =V34/3267379 -> 0.69355223 | W31: =W34/3267379 -> 0.67608159 | X31: =X34/3267379 -> 0.67608159 | Z31: 0 | AA31: 0.25 | AB31: 0.25 | AD31: - | AE31: =(Z31-I31)/10 -> 0.014693035
A32: Home Equity | B32: 0 | C32: 0 | D32: 3074.3907 | E32: 12122.72 | F32: 22075.825 | G32: 31799.357 | H32: 19210 | I32: -44152.571 | J32: -36763.754 | K32: -28936.093 | L32: -20643.47 | M32: 3185.3837 | N32: 3185.3837 | O32: 3185.3837 | P32: 0 | Q32: 0 | R32: 0 | S32: =R32 -> 0 | T32: =3267379-T34 -> 895770 | U32: =3267379-U34 -> 945609 | V32: =3267379-V34 -> 1001281 | W32: =3267379-W36 -> 1058364.2 | X32: =3267379-X36 -> 1058364.2 | Z32: 0 | AA32: 0 | AB32: 0 | AD32: - | AE32: -
A33: YoY Change | B33: --- | C33: --- | D33: ---- | E33: 2.9431294 | F33: 0.82102896 | G33: 0.44046064 | H33: -0.39589974 | I33: - | J33: - | K33: - | L33: - | M33: - | N33: 0 | O33: 0 | P33: -1 | Q33: 0 | R33: 0 | S33: 0 | T33: 0 | U33: 0 | V33: 0 | W33: 0 | X33: 0 | Z33: 0 | AA33: 0 | AB33: 0 | AD33: -
A34: Mortgage | B34: 0 | C34: 0 | D34: 297325.61 | E34: 288277.28 | F34: 278324.17 | G34: 268600.64 | H34: 255790 | I34: 249152.57 | J34: 241763.75 | K34: 233936.09 | L34: 225643.47 | M34: 201814.62 | N34: 197000 | O34: 197000 | P34: 0 | Q34: 0 | R34: 0 | S34: =S36+S37 -> 0 | T34: 2371609 | U34: =SUM(U36+U37) -> 2321770 | V34: =V36+V37 -> 2266098 | W34: =W36+W37 -> 2209014.8 | X34: =X36+X37 -> 2209014.8 | Z34: 0 | AA34: 0 | AB34: 0 | AC34: =(R34-O34)/O34 -> -1 | AD34: =(Z34-I34)/I34 -> -1 | AE34: =(Z34-I34)/10 -> -24915.257
A35: YoY Change | E35: -0.030432393 | F35: -0.03452615 | G35: -0.034935995 | H35: -0.047694014 | I35: -0.025948744 | J35: -0.02965579 | K35: -0.032377318 | L35: -0.035448237 | M35: -0.105604 | N35: -0.023856628 | O35: 0 | P35: -1 | Q35: - | R35: - | S35: - | T35: - | U35: - | V35: - | W35: - | X35: - | Z35: - | AA35: - | AB35: - | AD35: - | AE35: -
A36: Mortgage 1 | B36: 0 | C36: 0 | D36: 238579.07 | E36: 235042.72 | F36: 230519.01 | G36: 226559.74 | H36: 218784.9 | I36: 215752.76 | J36: 212549.59 | K36: 209165.73 | L36: 205590.99 | M36: 201814.62 | N36: 197000 | O36: 197000 | P36: 0 | Q36: 0 | R36: 0 | S36: 0 | T36: 2371609 | U36: 2321770 | V36: 2266098 | W36: 2209014.8 | X36: 2209014.8 | Z36: 0 | AA36: 2435000 | AB36: 2435000 | AD36: - | AE36: -
A37: Mortgage 2 | B37: 0 | C37: 0 | D37: 58746.538 | E37: 53234.556 | F37: 47805.166 | G37: 42040.902 | H37: 37342.287 | I37: 33399.809 | J37: 29214.167 | K37: 24770.363 | L37: 20052.476 | M37: 0 | N37: 0 | O37: 0 | P37: 0 | Q37: 0 | R37: 0 | S37: 0 | T37: 0 | U37: 0 | V37: 0 | W37: 0 | X37: 0 | Z37: 0 | AA37: 0 | AB37: 0
A38: Net Worth **** | B38: =B26+B32 -> -2700 | C38: =C26+C32 -> 38927 | D38: =D26+D32 -> 99701.391 | E38: =E26+E32 -> 151332.72 | F38: =F26+F32 -> 245591.83 | G38: =G26+G32 -> 332882.36 | H38: =H26+H32 -> 291716 | I38: =I26+I32 -> 377597.43 | ... X38: =X26+X32 -> 5457807 | Z38: =Z26+Z32 -> 3325935 | AA38: =AA26+AA32 -> 2578108 | AB38: =AB26+AB32 -> 3488855 | AC38: =(R38-O38)/O38 -> 0.77699564 | AD38: =(Z38-I38)/I38 -> 7.8081505 | AE38: =(Z38-I38)/10 -> 294833.76 | AH38: =663901-T42 -> 385984.4
A39: YoY Change | C39: =(C38-B38) -> 41627 | D39: =(D38-C38) -> 60774.391 | E39: =(E38-D38) -> 51631.33 | F39: =(F38-E38) -> 94259.105 | G39: =(G38-F38) -> 87290.532 | H39: =(H38-G38) -> -41166.357 | I39: =(I38-H38) -> 85881.429 | J39: =(J38-I38) -> 176941.82 | ... V39: =(V38-U38) -> 198369 | W39: =(W38-U39) -> 5166159 | X39: =(X38-V38) -> 1299829 | Z39: =(Z38-X38) -> -2131872 | AA39: =(AA38-Z38) -> -747827 | AB39: =(AB38-AA38) -> 910747 | AD39: =(Z39-I39)/I39 -> -25.823434 | AE39: =(Z39-I39)/10 -> -221775.34
A40: YoY Change (%) | B40: --- | C40: =(C38-B38)/B38 -> -15.417407 | D40: =(D38-C38)/C38 -> 1.56124 | E40: =(E38-D38)/D38 -> 0.51785967 | F40: =(F38-E38)/E38 -> 0.62286004 | G40: =(G38-F38)/F38 -> 0.35542931 | H40: =(H38-G38)/G38 -> -0.12366638 | I40: =(I38-H38)/H38 -> 0.29440082 | J40: =(J38-I38)/I38 -> 0.4685991 | ... V40: =(V38-U38)/U38 -> 0.050098128 | W40: =(W38-U39)/U39 -> 85.536683 | X40: =(X38-V38)/V38 -> 0.31261083 | Z40: =(Z38-X38)/X38 -> -0.39060963 | AA40: =(AA38-Z38)/Z38 -> -0.22484715 | AB40: =(AB38-AA38)/AA38 -> 0.35326177
A41: Income
A42: Income R | B42: 72015.84 | C42: 72883 | D42: 78693 | E42: 80432 | F42: 92844 | G42: 102510 | H42: 107237 | I42: 126931 | J42: 123458.78 | K42: 131775 | L42: 139708 | M42: 143728 | N42: 153511 | O42: 179905 | P42: 217425 | Q42: 323386 | R42: 245200 | S42: 245735 | T42: 277916.6 | U42: 306582.43 | V42: =280458.32+ 64928.5 -> 345386.82 | W42: 519947.38 | X42: 519947.38 | Z42: 245735 | AA42: 245200 | AB42: 245200 | AC42: =(R42-O42)/O42 -> 0.36294155 | AD42: =(S42-P42)/P42 -> 0.13020582 | AE42: =(T42-Q42)/Q42 -> -0.14060411
A43: YoY | B43: =(B42-49315-3000)/(49315+3000) -> 0.3765811 | C43: =(C42-B42)/B42 -> 0.01204124 | D43: =(D42-C42)/C42 -> 0.079716806 | E43: =(E42-D42)/D42 -> 0.022098535 | F43: =(F42-E42)/E42 -> 0.15431669 | G43: =(G42-F42)/F42 -> 0.10411012 | H43: =(H42-G42)/G42 -> 0.046112574 | I43: =(I42-H42)/H42 -> 0.1836493 | J43: =(J42-I42)/I42 -> -0.027355177 | ... W43: =(W42-V42)/V42 -> 0.50540597 | X43: =(X42-V42)/V42 -> 0.50540597 | Z43: =(Z42-X42)/X42 -> -0.52738487 | AA43: =(AA42-Z42)/Z42 -> -0.002177142 | AB43: =(AB42-AA42)/AA42 -> 0
A44: CAGR | B44: =POWER(B42/72000, 1/B9)-1 -> 0.00022 | C44: =POWER(C42/72000, 1/C9)-1 -> 0.0061132585 | D44: =POWER(D42/72000, 1/D9)-1 -> 0.030072679 | E44: =POWER(E42/72000, 1/E9)-1 -> 0.02807333 | F44: =POWER(F42/72000, 1/F9)-1 -> 0.052166013 | G44: =POWER(G42/72000, 1/G9)-1 -> 0.060650472 | H44: =POWER(H42/72000, 1/H9)-1 -> 0.058561325 | I44: =POWER(I42/72000, 1/I9)-1 -> 0.073444019 | ... X44: =POWER(X42/72000, 1/X9)-1 -> 0.08976186 | Z44: =POWER(Z42/72000, 1/Z9)-1 -> 0.070578665 | AA44: =POWER(AA42/72000, 1/AA9)-1 -> 0.070449043 | AB44: =POWER(AB42/72000, 1/AB9)-1 -> 0.041692648
A45: Income S | B45: 44442 | C45: 65729 | D45: 67442 | E45: 79608 | F45: 90760 | G45: 93773 | H45: 97767 | I45: 86678 | J45: 110788 | K45: 110000 | L45: 116037 | M45: 132572 | N45: 141359 | O45: 162697 | P45: 168200 | Q45: 230386 | R45: 276835 | S45: =170906 + 116873 -> 287779 | T45: 276835 | U45: 278512.23 | V45: 411915.6 | W45: 463790.18 | X45: 463790.18 | Z45: 276835 | AA45: 276835 | AB45: 276835 | AC45: =(R45-O45)/O45 -> 0.70153721 | AD45: =(S45-P45)/P45 -> 0.71093341 | AE45: =(T45-Q45)/Q45 -> 0.20161381
A46: YoY | B46: =(B45-20000)/(20000) -> 1.2221 | C46: =(C45-B45)/B45 -> 0.47898384 | D46: =(D45-C45)/C45 -> 0.026061556 | E46: =(E45-D45)/D45 -> 0.18039204 | F46: =(F45-E45)/E45 -> 0.14008642 | G46: =(G45-F45)/F45 -> 0.033197444 | H46: =(H45-G45)/G45 -> 0.042592217 | I46: =(I45-H45)/H45 -> -0.11342273 | J46: =(J45-I45)/I45 -> 0.27815593 | ... W46: =(W45-V45)/V45 -> 0.12593497 | X46: =(X45-V45)/V45 -> 0.12593497 | Z46: =(Z45-X45)/X45 -> -0.40310293 | AA46: =(AA45-Z45)/Z45 -> 0 | AB46: =(AB45-AA45)/AA45 -> 0
A47: CAGR | B47: --- | C47: =POWER(C42/65000, 1/(C9-1))-1 -> 0.12127692 | D47: =POWER(D42/65000, 1/(D9-1))-1 -> 0.10030066 | E47: =POWER(E42/65000, 1/(E9-1))-1 -> 0.073590114 | F47: =POWER(F42/65000, 1/(F9-1))-1 -> 0.093226427 | G47: =POWER(G42/65000, 1/(G9-1))-1 -> 0.095394549 | H47: =POWER(H42/65000, 1/(H9-1))-1 -> 0.087022541 | I47: =POWER(I42/65000, 1/(I9-1))-1 -> 0.10032771 | J47: =POWER(J42/65000, 1/(J9-1))-1 -> 0.083492921 | ... X47: =POWER(X42/65000, 1/(X9-1))-1 -> 0.099126167 | Z47: =POWER(Z42/65000, 1/(Z9-1))-1 -> 0.081368575 | AA47: =POWER(AA42/65000, 1/(AA9-1))-1 -> 0.081229945 | AB47: =POWER(AB42/65000, 1/(AB9-1))-1 -> 0.046846496
...

Sheet Comp
C3: Curr | D3: New | E3: Delta | F3: %
B4: SRP | C4: 233600 | D4: 265188 | E4: =D4-C4 -> 31588 | F4: =(D4-C4)/C4 -> 0.1352226 | G4: Base
C5: 45000 | D5: 55900 | E5: =D5-C5 -> 10900 | F5: =(D5-C5)/C5 -> 0.24222222 | G5: Var
C6: =C4+C5 -> 278600 | D6: =D4+D5 -> 321088 | E6: =D6-C6 -> 42488 | F6: =(D6-C6)/C6 -> 0.15250538 | G6: Total
B9: RDP | C9: 252000 | D9: 285750 | E9: =D9-C9 -> 33750 | F9: =(D9-C9)/C9 -> 0.13392857 | G9: Base
C10: 30000 | D10: 71370 | E10: =D10-C10 -> 41370 | F10: =(D10-C10)/C10 -> 1.379 | G10: Var
C11: =C9+C10 -> 282000 | D11: =D9+D10 -> 357120 | E11: =E9+E10 -> 75120 | F11: =(D11-C11)/C11 -> 0.26638298 | G11: Total
B13: HH | C13: =C9+C4 -> 485600 | D13: =D9+D4 -> 550938 | E13: =D13-C13 -> 65338 | F13: =(D13-C13)/C13 -> 0.13455107 | G13: Base
C14: =C5+C10 -> 75000 | D14: =D5+D10 -> 127270 | E14: =D14-C14 -> 52270 | F14: =(D14-C14)/C14 -> 0.69693333 | G14: Var
C15: =C6+C11 -> 560600 | D15: =D6+D11 -> 678208 | E15: =D15-C15 -> 117608 | F15: =(D15-C15)/C15 -> 0.20978951 | G15: Total
C42: CitiNRI | D42: 31/3/22 | E42: 1399
D43: 30/6/22 | E43: 1254
D44: 31/12/22 | E44: 1315
E46: =SUM(E42:E44) -> 3968
E47: =E46/70 -> 56.685714

Sheet Financials & Forecast
A2: Income Statement | B2: 2002 | C2: 2003 | D2: 2004 | E2: 2005 | F2: 2006 | G2: 2007 | H2: 2008 | I2: 2009 | J2: 2010 | K2: 2011 | L2: 2012 | M2: 2013 | N2: 2014 | O2: 2015 | P2: 2016 | Q2: 2017 | R2: 2018 | S2: 2019E | T2: 2019E | U2: 2019E
A3: Earnings | B3: =FinSnapshot!B60 -> 116457.84 | C3: =FinSnapshot!C60 -> 138612 | D3: =FinSnapshot!D60 -> 146135 | E3: =FinSnapshot!E60 -> 160040 | F3: =FinSnapshot!F60 -> 183604 | G3: =FinSnapshot!G60 -> 196283 | H3: =FinSnapshot!H60 -> 205004 | I3: =FinSnapshot!I60 -> 213609 | ... U3: =FinSnapshot!U60 -> 585094.66
A4: Expenses | B4: =FinSnapshot!B112 -> 69054 | C4: =FinSnapshot!C112 -> 74224 | D4: =FinSnapshot!D112 -> 79170 | E4: =FinSnapshot!E112 -> 82173 | F4: =FinSnapshot!F112 -> 81548 | G4: =FinSnapshot!G112 -> 89971 | H4: =FinSnapshot!H112 -> 82506.566 | I4: =FinSnapshot!I112 -> 83029.687 | ... U4: =FinSnapshot!U112 -> 236052.19
A5: Gross Income | B5: =B3-B4 -> 47403.84 | C5: =C3-C4 -> 64388 | D5: =D3-D4 -> 66965 | E5: =E3-E4 -> 77867 | F5: =F3-F4 -> 102056 | G5: =G3-G4 -> 106312 | H5: =H3-H4 -> 122497.43 | I5: =I3-I4 -> 130579.31 | ... U5: =U3-U4 -> 349042.47
A6: Taxes | B6: =FinSnapshot!B85 -> 29052 | C6: =FinSnapshot!C85 -> 42602 | D6: =FinSnapshot!D85 -> 42534 | E6: =FinSnapshot!E85 -> 55198 | F6: =FinSnapshot!F85 -> 54583 | G6: =FinSnapshot!G85 -> 54767 | H6: =FinSnapshot!H85 -> 58590.58 | I6: =FinSnapshot!I85 -> 64687 | ... U6: =FinSnapshot!U85 -> 192614
A7: Income after taxes | B7: =B5-B6 -> 18351.84 | C7: =C5-C6 -> 21786 | D7: =D5-D6 -> 24431 | E7: =E5-E6 -> 22669 | F7: =F5-F6 -> 47473 | G7: =G5-G6 -> 51545 | H7: =H5-H6 -> 63906.854 | I7: =I5-I6 -> 65892.313 | ... U7: =U5-U6 -> 156428.47
A8: Non-Operating Expenses | B8: =FinSnapshot!B91 -> 1514 | C8: =FinSnapshot!C91 -> 1814 | D8: =FinSnapshot!D91 -> 956 | E8: =FinSnapshot!E91 -> 1796 | F8: =FinSnapshot!F91 -> 2018 | G8: =FinSnapshot!G91 -> 2516 | H8: =FinSnapshot!H91 -> 2478 | I8: =FinSnapshot!I91 -> 3852 | ... U8: =FinSnapshot!U91 -> 5732
A9: Income | B9: =B7-B8 -> 16837.84 | C9: =C7-C8 -> 19972 | D9: =D7-D8 -> 23475 | E9: =E7-E8 -> 20873 | F9: =F7-F8 -> 45455 | G9: =G7-G8 -> 49029 | H9: =H7-H8 -> 61428.854 | I9: =I7-I8 -> 62040.313 | ... U9: =U7-U8 -> 150696.47
A10: Other Income (Div/ Interest) | B10: =FinSnapshot!B52 -> 309 | C10: =FinSnapshot!C52 -> 589 | D10: =FinSnapshot!D52 -> 955 | E10: =FinSnapshot!E52 -> 1555 | F10: =FinSnapshot!F52 -> 3301 | G10: =FinSnapshot!G52 -> 5075 | H10: =FinSnapshot!H52 -> -7531 | I10: =FinSnapshot!I52 -> 6054 | ... U10: =FinSnapshot!U52 -> 18896
A11: Non Operating Income | B11: 0 | C11: 0 | D11: 0 | E11: 0 | F11: 0 | G11: 0 | H11: 0 | I11: 0 | J11: 0 | K11: 0 | L11: 0 | M11: 0 | N11: 0 | O11: 0 | P11: 0 | Q11: 0 | R11: 0 | S11: 0 | T11: 0 | U11: 0
A12: Net Income | B12: =SUM(B9+B10) -> 17146.84 | C12: =SUM(C9+C10) -> 20561 | D12: =SUM(D9+D10) -> 24430 | E12: =SUM(E9+E10) -> 22428 | F12: =SUM(F9:F11) -> 48756 | G12: =SUM(G9+G10) -> 54104 | H12: =SUM(H9+H10) -> 53897.854 | I12: =SUM(I9+I10) -> 68094.313 | J12: =SUM(J9+J10) -> 51361.381 | K12: =SUM(K9+K10) -> 77899.685 | L12: =SUM(L9+L10) -> 65061.601 | M12: =SUM(M9+M10) -> 67187.2 | N12: =SUM(N9+N10) -> 78566 | ... U12: =SUM(U9+U10) -> 169592.47
A13: Net Profit Margin | B13: =B12/B3 -> 0.14723646 | C13: =C12/C3 -> 0.14833492 | D13: =D12/D3 -> 0.16717419 | E13: =E12/E3 -> 0.14013997 | F13: =F12/F3 -> 0.26554977 | G13: =G12/G3 -> 0.27564282 | H13: =H12/H3 -> 0.26291123 | I13: =I12/I3 -> 0.31878017 | ... U13: =U12/U3 -> 0.28985475
A14: Actual Increase in assets | C14: =FinSnapshot!$C$28-FinSnapshot!$B$28 -> 34127 | D14: =FinSnapshot!$D$28-FinSnapshot!$C$28 -> 32000 | E14: =FinSnapshot!$E$28-FinSnapshot!$D$28 -> 38895 | F14: =FinSnapshot!$F$28-FinSnapshot!$E$28 -> 83694 | G14: =FinSnapshot!$G$28-FinSnapshot!$F$28 -> 91067 | H14: =FinSnapshot!$H$28-FinSnapshot!$G$28 -> -42077 | I14: =FinSnapshot!$I$28-FinSnapshot!$H$28 -> 166744 | J14: =FinSnapshot!$J$28-FinSnapshot!$I$28 -> 169553 | K14: =FinSnapshot!$K$28-FinSnapshot!$J$28 -> 94736 | L14: =FinSnapshot!$L$28-FinSnapshot!$K$28 -> 148051 | M14: =FinSnapshot!$M$28-FinSnapshot!$L$28 -> 310359 | N14: =FinSnapshot!$N$28-FinSnapshot!$M$28 -> 258889 | O14: =FinSnapshot!$O$28-FinSnapshot!$N$28 -> 103569 | P14: =FinSnapshot!$P$28-FinSnapshot!$O$28 -> 489968 | Q14: =FinSnapshot!$O$28-FinSnapshot!$N$28 -> 103569 | R14: =FinSnapshot!$O$28-FinSnapshot!$N$28 -> 103569 | S14: =FinSnapshot!$O$28-FinSnapshot!$N$28 -> 103569 | T14: =FinSnapshot!$O$28-FinSnapshot!$N$28 -> 103569 | U14: =FinSnapshot!$O$28-FinSnapshot!$N$28 -> 103569
B15: 2015 | C15: 2016 E | D15: 2017 E | E15: 2018 E | F15: 2019 E | G15: 2020 E | H15: 2021 E | I15: 2022 E | J15: 2023 E | K15: 2024 E | L15: 2025 E
A16: Housing | B16: =Monthly!C864 -> 1655 | C16: =B16*(1+$B$39) -> 1737.75 | D16: =4500*12/$B$40 -> 54000 | E16: =D16*(1+$B$39) -> 56700 | F16: =E16*(1+$B$39) -> 59535 | G16: =F16*(1+$B$39) -> 62511.75 | H16: =G16*(1+$B$39) -> 65637.338 | I16: =H16*(1+$B$39) -> 68919.204 | J16: =I16*(1+$B$39) -> 72365.165 | K16: =J16*(1+$B$39) -> 75983.423 | L16: =K16*(1+$B$39) -> 79782.594
A17: Car | B17: =Monthly!C878 -> 491 | C17: =B17*(1+$B$38) -> 662.85 | D17: =(C17*(1+$B$39) + 800*12)/$B$40 -> 10295.993 | E17: =(C17*(1+$B$39) + 800*12)/$B$40 -> 10295.993 | F17: =(C17*(1+$B$39) + 1600*12)/$B$40 -> 19895.993 | G17: =(C17*(1+$B$39) + 1600*12)/$B$40 -> 19895.993 | H17: =(C17*(1+$B$39) + 1600*12)/$B$40 -> 19895.993 | I17: =(C17*(1+$B$39) + 1600*12)/$B$40 -> 19895.993 | J17: =(C17*(1+$B$39) + 1600*12)/$B$40 -> 19895.993 | K17: =($C$17*1.5 + 800*12)/$B$40 -> 10594.275 | L17: =($C$17*1.5 + 800*12)/$B$40 -> 10594.275
A18: Transportation | B18: =Monthly!C886 -> 246 | C18: =B18*(1+$B$38) -> 332.1 | D18: =C18*(1+$B$39) -> 348.705 | E18: =D18*(1+$B$39) -> 366.14025 | F18: =E18*(1+$B$39) -> 384.44726 | G18: =F18*(1+$B$39) -> 403.66963 | H18: =G18*(1+$B$39) -> 423.85311 | I18: =H18*(1+$B$39) -> 445.04576 | J18: =I18*(1+$B$39) -> 467.29805 | K18: =J18*(1+$B$39) -> 490.66295 | L18: =K18*(1+$B$39) -> 515.1961
A19: Food | B19: =Monthly!C892 -> 993 | C19: =B19*(1+$B$38) -> 1340.55 | D19: =C19*(1+$B$39) -> 1407.5775 | E19: =D19*(1+$B$39) -> 1477.9564 | F19: =E19*(1+$B$39) -> 1551.8542 | G19: =F19*(1+$B$39) -> 1629.4469 | H19: =G19*(1+$B$39) -> 1710.9192 | I19: =H19*(1+$B$39) -> 1796.4652 | J19: =I19*(1+$B$39) -> 1886.2885 | K19: =J19*(1+$B$39) -> 1980.6029 | L19: =K19*(1+$B$39) -> 2079.633
A20: Utilities | B20: =Monthly!C896 -> 463 | C20: =B20*(1+$B$38) -> 625.05 | D20: =C20*(1+$B$39) -> 656.3025 | E20: =D20*(1+$B$39) -> 689.11763 | F20: =E20*(1+$B$39) -> 723.57351 | G20: =F20*(1+$B$39) -> 759.75218 | H20: =G20*(1+$B$39) -> 797.73979 | I20: =H20*(1+$B$39) -> 837.62678 | J20: =I20*(1+$B$39) -> 879.50812 | K20: =J20*(1+$B$39) -> 923.48353 | L20: =K20*(1+$B$39) -> 969.6577
A21: Misc | B21: =Monthly!C906 -> 129 | C21: =B21*(1+$B$38) -> 174.15 | D21: =C21*(1+$B$39) -> 182.8575 | E21: =D21*(1+$B$39) -> 192.00038 | F21: =E21*(1+$B$39) -> 201.60039 | G21: =F21*(1+$B$39) -> 211.68041 | H21: =G21*(1+$B$39) -> 222.26443 | I21: =H21*(1+$B$39) -> 233.37766 | J21: =I21*(1+$B$39) -> 245.04654 | K21: =J21*(1+$B$39) -> 257.29887 | L21: =K21*(1+$B$39) -> 270.16381
A22: Trips (EET) | B22: =Monthly!C914 -> 0 | C22: =B22*(1+$B$38) -> 0 | D22: =C22*(1+$B$39) -> 0 | E22: =D22*(1+$B$39) -> 0 | F22: =E22*(1+$B$39) -> 0 | G22: =F22*(1+$B$39) -> 0 | H22: =G22*(1+$B$39) -> 0 | I22: =H22*(1+$B$39) -> 0 | J22: =I22*(1+$B$39) -> 0 | K22: =J22*(1+$B$39) -> 0 | L22: =K22*(1+$B$39) -> 0
A23: School | B23: =Monthly!O917 -> 576.58333 | C23: =B23*(1+$B$38) -> 778.3875 | D23: =((C23)*(1+$B$39)) -> 817.30688 | E23: =((D23)*(1+$B$39)) -> 858.17222 | F23: =((E23)*(1+$B$39)) -> 901.08083 | G23: =((F23)*(1+$B$39)) -> 946.13487 | H23: =((G23)*(1+$B$39)) -> 993.44161 | I23: =((H23)*(1+$B$39)) -> 1043.1137 | J23: =((I23)*(1+$B$39)) -> 1095.2694 | K23: =((J23)*(1+$B$39)) -> 1150.0328 | L23: =((K23)*(1+$B$39)) -> 1207.5345
A24: Day Care/ Extra Classes | B24: =Monthly!O918 -> 1891.4167 | C24: =B24*(1+$B$38) -> 2553.4125 | D24: =(C24*(1+$B$39)) -> 2681.0831 | E24: =(D24*(1+$B$39)) -> 2815.1373 | F24: =(E24*(1+$B$39)) -> 2955.8941 | G24: =(F24*(1+$B$39)) -> 3103.6889 | H24: =(G24*(1+$B$39)) -> 3258.8733 | I24: =(H24*(1+$B$39)) -> 3421.817 | J24: =(I24*(1+$B$39)) -> 3592.9078 | K24: =(J24*(1+$B$39)) -> 3772.5532 | L24: =(K24*(1+$B$39)) -> 3961.1809
A25: Medical | B25: =FinSnapshot!P102/B40 -> 3921 | C25: =B25*(1+$B$38) -> 5293.35 | D25: =(C25*(1+$B$39)) -> 5558.0175 | E25: =(D25*(1+$B$39)) -> 5835.9184 | F25: =(E25*(1+$B$39)) -> 6127.7143 | G25: =(F25*(1+$B$39)) -> 6434.1 | H25: =(G25*(1+$B$39)) -> 6755.805 | I25: =(H25*(1+$B$39)) -> 7093.5953 | J25: =(I25*(1+$B$39)) -> 7448.275 | K25: =(J25*(1+$B$39)) -> 7820.6888 | L25: =(K25*(1+$B$39)) -> 8211.7232
A26: OTE | B26: =Monthly!O929 -> 53.166667 | C26: =B26*(1+$B$38) -> 71.775 | D26: =(C26*(1+$B$39)) -> 75.36375 | E26: =(D26*(1+$B$39)) -> 79.131938 | F26: =(E26*(1+$B$39)) -> 83.088534 | G26: =(F26*(1+$B$39)) -> 87.242961 | H26: =(G26*(1+$B$39)) -> 91.605109 | I26: =(H26*(1+$B$39)) -> 96.185365 | J26: =(I26*(1+$B$39)) -> 100.99463 | K26: =(J26*(1+$B$39)) -> 106.04436 | L26: =(K26*(1+$B$39)) -> 111.34658
A27: Non Opex | B27: =(FinSnapshot!P91 - B25)/B40 -> 2741 | C27: =B27*(1+$B$38) -> 3700.35 | D27: =(C27*(1+$B$39)) -> 3885.3675 | E27: =(D27*(1+$B$39)) -> 4079.6359 | F27: =(E27*(1+$B$39)) -> 4283.6177 | G27: =(F27*(1+$B$39)) -> 4497.7986 | H27: =(G27*(1+$B$39)) -> 4722.6885 | I27: =(H27*(1+$B$39)) -> 4958.8229 | J27: =(I27*(1+$B$39)) -> 5206.764 | K27: =(J27*(1+$B$39)) -> 5467.1023 | L27: =(K27*(1+$B$39)) -> 5740.4574
A28: India | B28: =Monthly!O930 -> 750 | C28: =B28*(1+$B$38) -> 1012.5 | D28: =12000/$B$40 -> 12000 | E28: =12000/$B$40 -> 12000 | F28: =12000/$B$40 -> 12000 | G28: =12000/$B$40 -> 12000 | H28: =12000/$B$40 -> 12000 | I28: =12000/$B$40 -> 12000 | J28: =12000/$B$40 -> 12000 | K28: =12000/$B$40 -> 12000 | L28: =12000/$B$40 -> 12000
A29: Expenses | B29: =SUM(B16:B26) -> 10419.167 | C29: =SUM(C16:C26) -> 13569.375 | D29: =SUM(D16:D26) -> 76023.206 | E29: =SUM(E16:E26) -> 79309.567 | F29: =SUM(F16:F26) -> 92360.246 | G29: =SUM(G16:G26) -> 95983.458 | H29: =SUM(H16:H26) -> 99787.832 | I29: =SUM(I16:I26) -> 103782.42 | ... L29: =SUM(L16:L26) -> 107703.3
A30: Taxes | B30: =FinSnapshot!O85/B40 -> 112773 | C30: =C32*$B$38 -> 123508.02 | D30: =D32*$B$38 -> 127213.26 | E30: =E32*$B$38 -> 131029.66 | F30: =F32*$B$38 -> 134960.55 | G30: =G32*$B$38 -> 139009.37 | H30: =H32*$B$38 -> 143179.65 | I30: =I32*$B$38 -> 147475.04 | J30: =J32*$B$38 -> 151899.29 | ... L30: =L32*$B$38 -> 161149.95
A31: Total Expenses | B31: =Monthly!O934 -> 8969.25 | C31: =Monthly!O857 -> 9854.0833 | D31: =SUM(D16:D30)/1 - D29 -> 219121.84 | E31: =SUM(E16:E30)/1 - E29 -> 226418.86 | F31: =SUM(F16:F30)/1 - F29 -> 243604.41 | G31: =SUM(G16:G30)/1 - G29 -> 251490.62 | H31: =SUM(H16:H30)/1 - H29 -> 259690.17 | I31: =SUM(I16:I30)/1 - I29 -> 268216.28 | J31: =SUM(J16:J30)/1 - J29 -> 277082.8 | K31: =SUM(K16:K30)/1 - K29 -> 277002.43 | L31: =SUM(L16:L30)/1 - L29 -> 286593.72
A32: Household Income | B32: =FinSnapshot!O60/$B$40 -> 342602 | C32: =(B32*(1+$B$42)) -> 352880.06 | D32: =(C32*(1+$B$42)) -> 363466.46 | E32: =(D32*(1+$B$42)) -> 374370.46 | F32: =(E32*(1+$B$42)) -> 385601.57 | G32: =(F32*(1+$B$42)) -> 397169.62 | H32: =(G32*(1+$B$42)) -> 409084.7 | I32: =(H32*(1+$B$42)) -> 421357.25 | J32: =(I32*(1+$B$42)) -> 433997.96 | ... L32: =(K32*(1+$B$42)) -> 460428.44
A33: Investments | B33: =80000/$B$40 -> 80000 | C33: =80000/$B$40 -> 80000 | D33: =80000/$B$40 -> 80000 | E33: =80000/$B$40 -> 80000 | F33: =80000/$B$40 -> 80000 | G33: =80000/$B$40 -> 80000 | H33: =80000/$B$40 -> 80000 | I33: =80000/$B$40 -> 80000 | ... L33: =80000/$B$40 -> 80000
A34: 529 Plan | B34: =20000/$B$40 -> 20000 | C34: =20000/$B$40 -> 20000 | D34: =20000/$B$40 -> 20000 | E34: =20000/$B$40 -> 20000 | F34: =20000/$B$40 -> 20000 | G34: =20000/$B$40 -> 20000 | H34: =20000/$B$40 -> 20000 | I34: =20000/$B$40 -> 20000 | ... L34: =20000/$B$40 -> 20000
A35: Savings | B35: =(B32-B33-B34-B31)/$B$40 -> 233632.75 | C35: =(C32-C33-C34-C31)/$B$40 -> 243025.98 | D35: =(D32-D33-D34-D31)/$B$40 -> 44344.626 | E35: =(E32-E33-E34-E31)/$B$40 -> 47951.593 | F35: =(F32-F33-F34-F31)/$B$40 -> 41997.157 | G35: =(G32-G33-G34-G31)/$B$40 -> 45678.994 | H35: =(H32-H33-H34-H31)/$B$40 -> 49394.538 | I35: =(I32-I33-I34-I31)/$B$40 -> 53140.963 | ... L35: =(L32-L33-L34-L31)/$B$40 -> 73834.723
A37: COLA | B37: 0.5
A38: Tax Rate | B38: 0.35
A39: Inflation | B39: 0.05
A40: Monthly | B40: 1
A41: Investments /yr contr growth | B41: 0
A42: Avg Income Growth | B42: 0.03
...

Sheet M
B1: 2002 | C1: 2003 | D1: 2004 | E1: 2005 | F1: 2006 | G1: 2007 | H1: 2008 | I1: 2009 | J1: 2010 | K1: 2011 | L1: 2012 | M1: 2013 | N1: 2014 | O1: 2015 | P1: 2016 | Q1: 2017 | R1: 2018 | S1: 2019 | T1: 2020 | U1: 2021 | V1: 2022 | W1: 2023 | X1: Avg | Y1: Trends | Z1: Median | AA1: Max | AB1: Min
A2: Jan | B2: NA | C2: 4791 | D2: =Monthly!C$1784 -> 5167.1667 | E2: =Monthly!$C$1706 -> 6372.0833 | F2: =Monthly!C$1628 -> 5839.5833 | G2: =Monthly!C$1550 -> 9598.6667 | H2: =Monthly!C$1473 -> 10828.249 | I2: =Monthly!C$1396 -> 4603.823 | J2: =Monthly!C$1319 -> 11670.033 | K2: =Monthly!C$1241 -> 9174.6166 | L2: =Monthly!C$1164 -> 9285.5332 | M2: =Monthly!C$1087 -> 9994.6999 | N2: =Monthly!C$1010 -> 9449.1667 | O2: =Monthly!C$934 -> 7233.4167 | P2: =Monthly!C$857 -> 10627.917 | Q2: =Monthly!C$780 -> 12832.9 | R2: =Monthly!C703 -> 11992.5 | S2: =Monthly!C$626 -> 11212.5 | T2: =Monthly!C550 -> 16403.5 | U2: =Monthly!C473 -> 19249.967 | V2: =Monthly!C396 -> 37226.8 | W2: =Monthly!C312 -> 21040.633 | X2: =(SUM(C2:T2))/($B$34-1) -> 6961.5565 | Z2: =MEDIAN(B2:T2) -> 9523.9167 | AA2: =MAX(B2:T2) -> 16403.5 | AB2: =MIN(B2:T2) -> 4603.823
A3: Feb | B3: NA | C3: 4789 | D3: =Monthly!D$1784 -> 5284.1667 | E3: =Monthly!D$1706 -> 4553.0833 | F3: =Monthly!D$1628 -> 5277.5833 | G3: =Monthly!D$1550 -> 5674.6667 | H3: =Monthly!D$1473 -> 6757.2495 | I3: =Monthly!D$1396 -> 16616.491 | J3: =Monthly!D$1319 -> 7230.0332 | K3: =Monthly!D$1241 -> 9024.6999 | L3: =Monthly!D1164 -> 8761.5332 | M3: =Monthly!D$1087 -> 10482.7 | N3: =Monthly!D$1010 -> 6971.1667 | O3: =Monthly!D$934 -> 11151.417 | P3: =Monthly!D$857 -> 8998.9167 | Q3: =Monthly!D$780 -> 8990.9 | R3: =Monthly!D$703 -> 11070.5 | S3: =Monthly!D$626 -> 11427.5 | T3: =Monthly!D$550 -> 12072.5 | U3: =Monthly!D473 -> 17398.967 | V3: =Monthly!D396 -> 22335.125 | W3: =Monthly!D312 -> 16593.633 | X3: =(SUM(C3:T3))/($B$34-1) -> 6463.9211 | Z3: =MEDIAN(B3:T3) -> 8876.2166 | AA3: =MAX(B3:T3) -> 16616.491 | AB3: =MIN(B3:T3) -> 4553.0833
A4: Mar | B4: NA | C4: 5967 | D4: =Monthly!E$1784 -> 21805.167 | E4: =Monthly!E$1706 -> 7299.0833 | F4: =Monthly!E$1628 -> 5674.5833 | G4: =Monthly!E$1550 -> 8183.6667 | H4: =Monthly!E$1473 -> 7029.2495 | I4: =Monthly!E$1396 -> 7078.1617 | J4: =Monthly!E1319 -> 7665.0332 | K4: =Monthly!E$1241 -> 6130.6999 | L4: =Monthly!E$1164 -> 9062.5332 | M4: =Monthly!E$1087 -> 7952.6999 | N4: =Monthly!E$1010 -> 8020.1667 | O4: =Monthly!E$934 -> 8972.4167 | P4: =Monthly!E$857 -> 7265.9167 | Q4: =Monthly!E$780 -> 8806.9 | R4: =Monthly!E703 -> 11857.5 | S4: =Monthly!E$626 -> 9677.5 | T4: =Monthly!E$550 -> 10550.5 | U4: =Monthly!E473 -> 20023.967 | V4: =Monthly!E396 -> 27187.8 | W4: =Monthly!E312 -> 16992.633 | X4: =(SUM(C4:T4))/($B$34-1) -> 6624.9491 | Z4: =MEDIAN(B4:T4) -> 7986.4333 | AA4: =MAX(B4:T4) -> 21805.167 | AB4: =MIN(B4:T4) -> 5674.5833
A5: Apr | B5: NA | C5: 6991 | D5: =Monthly!F$1784 -> 4288.1667 | E5: =Monthly!F$1706 -> 4978.0833 | F5: =Monthly!F$1628 -> 12725.583 | G5: =Monthly!F$1550 -> 5737.6667 | H5: =Monthly!F$1473 -> 8759.2495 | I5: =Monthly!F$1396 -> 5574.8361 | J5: =Monthly!F$1319 -> 9896.0332 | K5: =Monthly!F$1241 -> 8064.6999 | L5: =Monthly!F$1164 -> 9753.5332 | M5: =Monthly!F$1087 -> 9141.6999 | N5: =Monthly!F$1010 -> 19469.167 | O5: =Monthly!F$934 -> 11032.417 | P5: =Monthly!F$857 -> 12264.917 | Q5: =Monthly!F$780 -> 11078.9 | R5: =Monthly!F703 -> 14610.5 | S5: =Monthly!F$626 -> 19728.5 | T5: =Monthly!F$550 -> 10159.5 | U5: =Monthly!F473 -> 18280.967 | V5: =Monthly!F396 -> 21155.8 | W5: =Monthly!F312 -> 24239.633 | X5: =(SUM(C5:T5))/($B$34-1) -> 7677.2688 | Z5: =MEDIAN(B5:T5) -> 9824.7832 | AA5: =MAX(B5:T5) -> 19728.5 | AB5: =MIN(B5:T5) -> 4288.1667
A6: May | B6: NA | C6: 5585 | D6: =Monthly!G$1784 -> 4218.1667 | E6: =Monthly!G$1706 -> 4643.0833 | F6: =Monthly!G$1628 -> 8793.5833 | G6: =Monthly!G$1550 -> 9511.6667 | H6: =Monthly!G$1473 -> 6834.2495 | I6: =Monthly!G$1396 -> 5204.5139 | J6: =Monthly!G$1319 -> 11692.033 | K6: =Monthly!G$1241 -> 9467.6999 | L6: =Monthly!G$1164 -> 10968.533 | M6: =Monthly!G$1087 -> 27395.25 | N6: =Monthly!G$1010 -> 9000.1667 | O6: =Monthly!G$934 -> 7590.4167 | P6: =Monthly!G$857 -> 6091.9167 | Q6: =Monthly!G$780 -> 10325.9 | R6: =Monthly!G703 -> 11106.5 | S6: =Monthly!G$626 -> 11871.5 | T6: =Monthly!G$550 -> 106767.33 | U6: =Monthly!G473 -> 18692.967 | V6: =Monthly!G396 -> 18135.8 | W6: =Monthly!G312 -> 19097.633 | X6: =(SUM(C6:T6))/($B$34-1) -> 11127.813 | Z6: =MEDIAN(B6:T6) -> 9233.9333 | AA6: =MAX(B6:T6) -> 106767.33 | AB6: =MIN(B6:T6) -> 4218.1667
A7: Jun | B7: NA | C7: 7709 | D7: =Monthly!H$1784 -> 5993.1667 | E7: =Monthly!H$1706 -> 5477.0833 | F7: =Monthly!H$1628 -> 8650.5833 | G7: =Monthly!H$1550 -> 8655.6667 | H7: =Monthly!H$1473 -> 9419.2495 | I7: =Monthly!H$1396 -> 7862.195 | J7: =Monthly!H$1319 -> 9412.0332 | K7: =Monthly!H$1241 -> 6516.6999 | L7: =Monthly!H$1164 -> 10179.533 | M7: =Monthly!H$1087 -> 10406.25 | N7: =Monthly!H$1010 -> 7495.1667 | O7: =Monthly!H$934 -> 8498.4167 | P7: =Monthly!H$857 -> 10510.917 | Q7: =Monthly!H$780 -> 12252.5 | R7: =Monthly!H703 -> 12425.5 | S7: =Monthly!H$626 -> 12699 | T7: =Monthly!H$550 -> 14815.5 | U7: =Monthly!H473 -> 20225.967 | V7: =Monthly!H396 -> 26746.8 | W7: =Monthly!H312 -> 22820.633 | X7: =(SUM(C7:T7))/($B$34-1) -> 7040.7692 | Z7: =MEDIAN(B7:T7) -> 9033.8499 | AA7: =MAX(B7:T7) -> 14815.5 | AB7: =MIN(B7:T7) -> 5477.0833
A8: Jul | B8: =Monthly!I1938 -> 5456.8333 | C8: 5900 | D8: =Monthly!I$1784 -> 5600.1667 | E8: =Monthly!I$1706 -> 5987.0833 | F8: =Monthly!I$1628 -> 5499.5833 | G8: =Monthly!I$1550 -> 7081.6667 | H8: =Monthly!I$1473 -> 6543.4352 | I8: =Monthly!$I$1396 -> 4673.8796 | J8: =Monthly!I$1319 -> 7790.0332 | K8: =Monthly!I$1241 -> 7044.6999 | L8: =Monthly!I$1164 -> 8539.5332 | M8: =Monthly!I$1087 -> 9164.25 | N8: =Monthly!I$1010 -> 12308.167 | O8: =Monthly!I$934 -> 8914.4167 | P8: =Monthly!I$857 -> 11037.25 | Q8: =Monthly!I$780 -> 15014.5 | R8: =Monthly!I703 -> 12768.5 | S8: =Monthly!I$626 -> 13387 | T8: =Monthly!I$550 -> 12328.5 | U8: =Monthly!I473 -> 19035.967 | V8: =Monthly!I396 -> 20303.8 | W8: =Monthly!I312 -> 29160.633 | X8: =(SUM(B8:T8))/($B$34-1) -> 6876.6457 | Z8: =MEDIAN(B8:T8) -> 7790.0332 | AA8: =MAX(B8:T8) -> 15014.5 | AB8: =MIN(B8:T8) -> 4673.8796
A9: Aug | B9: =Monthly!J$1938 -> 5662.8333 | C9: 5630 | D9: =Monthly!J$1784 -> 3364.1667 | E9: =Monthly!J$1706 -> 5948.0833 | F9: =Monthly!J$1628 -> 5795.5833 | G9: =Monthly!J$1550 -> 6232.6667 | H9: =Monthly!J$1473 -> 5047.4808 | I9: =Monthly!$J$1396 -> 4805.5676 | J9: =Monthly!J$1319 -> 14323.033 | K9: =Monthly!J$1241 -> 7836.6999 | L9: =Monthly!J$1164 -> 9616.5332 | M9: =Monthly!J$1087 -> 10647.25 | N9: =Monthly!J$1010 -> 9470.1667 | O9: =Monthly!J$934 -> 7069.4167 | P9: =Monthly!J$857 -> 7795.25 | Q9: =Monthly!J$780 -> 10862 | R9: =Monthly!J703 -> 10280.167 | S9: =Monthly!J$626 -> 11054 | T9: =Monthly!J$550 -> 10952.5 | U9: =Monthly!J473 -> 18994.058 | V9: =Monthly!J396 -> 50314.8 | W9: =Monthly!J312 -> 24057.633 | X9: =(SUM(B9:T9))/($B$34-1) -> 6349.7249 | Z9: =MEDIAN(B9:T9) -> 7795.25 | AA9: =MAX(B9:T9) -> 14323.033 | AB9: =MIN(B9:T9) -> 3364.1667
A10: Sep | B10: =Monthly!K$1938 -> 7364.8333 | C10: 6794 | D10: =Monthly!K$1784 -> 3667.1667 | E10: =Monthly!K$1706 -> 8321.0833 | F10: =Monthly!K$1628 -> 6247.5833 | G10: =Monthly!K$1550 -> 9424.6667 | H10: =Monthly!K$1473 -> 5837.0501 | I10: =Monthly!K$1396 -> 5329.259 | J10: =Monthly!K$1319 -> 12724.033 | K10: =Monthly!K$1241 -> 7861.6999 | L10: =Monthly!K$1164 -> 9328.5332 | M10: =Monthly!K$1087 -> 7533.25 | N10: =Monthly!K$1010 -> 8408.1667 | O10: =Monthly!K$934 -> 8576.4167 | P10: =Monthly!K$857 -> 8664.25 | Q10: =Monthly!K$780 -> 11410.5 | R10: =Monthly!K703 -> 16317.167 | S10: =Monthly!K$626 -> 14983 | T10: =Monthly!K$550 -> 69707.5 | U10: =Monthly!K473 -> 21111.872 | V10: =Monthly!K396 -> 19300.8 | W10: =Monthly!K312 -> 20546.633 | X10: =(SUM(B10:T10))/($B$34-1) -> 9520.84 | Z10: =MEDIAN(B10:T10) -> 8408.1667 | AA10: =MAX(B10:T10) -> 69707.5 | AB10: =MIN(B10:T10) -> 3667.1667
A11: Oct | B11: =Monthly!L$1938 -> 5230.8333 | C11: 7198 | D11: =Monthly!L$1784 -> 10177.167 | E11: =Monthly!L$1706 -> 15253.083 | F11: =Monthly!L$1628 -> 4554.5833 | G11: =Monthly!L$1550 -> 7160.6667 | H11: =Monthly!L$1473 -> 4859.0423 | I11: =Monthly!L$1396 -> 5249.9539 | J11: =Monthly!L$1319 -> 6941.0332 | K11: =Monthly!L$1241 -> 7059.6999 | L11: =Monthly!L$1164 -> 9311.5332 | M11: =Monthly!L$1087 -> 10955.25 | N11: =Monthly!L$1010 -> 7497.1667 | O11: =Monthly!L$934 -> 9452.4167 | P11: =Monthly!L$857 -> 9897.25 | Q11: =Monthly!L$780 -> 10009.5 | R11: =Monthly!L703 -> 9973.1667 | S11: =Monthly!L$626 -> 10662 | T11: =Monthly!L$550 -> 34119.167 | U11: =Monthly!L473 -> 23184.852 | V11: =Monthly!L396 -> 18289.8 | W11: =Monthly!L312 -> 22515.633 | X11: =(SUM(B11:T11))/($B$34-1) -> 7731.7297 | Z11: =MEDIAN(B11:T11) -> 9311.5332 | AA11: =MAX(B11:T11) -> 34119.167 | AB11: =MIN(B11:T11) -> 4554.5833
A12: Nov | B12: =Monthly!M$1938 -> 6914.8333 | C12: 5855 | D12: =Monthly!M$1784 -> 4857.1667 | E12: =Monthly!M$1706 -> 5164.0833 | F12: =Monthly!M$1628 -> 6491.5833 | G12: =Monthly!M$1550 -> 6183.6667 | H12: =Monthly!M$1473 -> 5084.0344 | I12: =Monthly!M$1396 -> 8362.6522 | J12: =Monthly!M$1319 -> 7833.0332 | K12: =Monthly!M$1241 -> 10236.7 | L12: =Monthly!M$1164 -> 11229.533 | M12: =Monthly!M$1087 -> 10874.25 | N12: =Monthly!M$1010 -> 11906.167 | O12: =Monthly!M$934 -> 9131.4167 | P12: =Monthly!M$857 -> 9158.25 | Q12: =Monthly!M$780 -> 10471.5 | R12: =Monthly!M703 -> 16661.167 | S12: =Monthly!M$626 -> 11502 | T12: =Monthly!M$550 -> 20456.8 | U12: =Monthly!M473 -> 18051.831 | V12: =Monthly!M396 -> 18987.8 | W12: =Monthly!M312 -> 22076.633 | X12: =(SUM(B12:T12))/($B$34-1) -> 7432.2432 | Z12: =MEDIAN(B12:T12) -> 9131.4167 | AA12: =MAX(B12:T12) -> 20456.8 | AB12: =MIN(B12:T12) -> 4857.1667
A13: Dec | B13: =Monthly!N$1938 -> 8423.8333 | C13: 7015 | D13: =Monthly!N$1784 -> 4748.1667 | E13: =Monthly!N$1706 -> 8177.0833 | F13: =Monthly!N$1628 -> 5997.5833 | G13: =Monthly!N$1550 -> 6525.6667 | H13: =Monthly!N$1473 -> 5508.0265 | I13: =Monthly!N$1396 -> 7668.3541 | J13: =Monthly!N$1319 -> 11992.033 | K13: =Monthly!N$1241 -> 8336.6999 | L13: =Monthly!N$1164 -> 11827.533 | M13: =Monthly!N$1087 -> 8987.25 | N13: =Monthly!N$1010 -> 7081.1667 | O13: =Monthly!N$934 -> 10008.417 | P13: =Monthly!N$857 -> 15936.25 | Q13: =Monthly!N$780 -> 11762.5 | R13: =Monthly!N703 -> 11240.167 | S13: =Monthly!N$626 -> 11631 | T13: =Monthly!N$550 -> 26284.217 | U13: =Monthly!N473 -> 21800.811 | V13: =Monthly!N396 -> 19823.8 | W13: =Monthly!N312 -> 18777.633 | X13: =(SUM(B13:T13))/($B$34-1) -> 7881.2895 | Z13: =MEDIAN(B13:T13) -> 8423.8333 | AA13: =MAX(B13:T13) -> 26284.217 | AB13: =MIN(B13:T13) -> 4748.1667
A14: Avg Exp. | B14: =(SUM(B8:B13))/6 -> 6509 | C14: =(SUM(C2:C13))/12 -> 6185.3333 | D14: =SUM(D2:D13)/12 -> 6597.5 | E14: =SUM(E2:E13)/12 -> 6847.75 | F14: =SUM(F2:F13)/12 -> 6795.6667 | G14: =SUM(G2:G10)/9 -> 7789 | H14: =SUM(H2:H13)/12 -> 6875.5472 | I14: =SUM(I2:I13)/12 -> 6919.1406 | J14: =SUM(J2:J13)/12 -> 9930.6999 | K14: =SUM(K2:K13)/12 -> 8062.943 | L14: =SUM(L2:L13)/12 -> 9822.0332 | M14: =SUM(M2:M13)/12 -> 11127.9 | N14: =SUM(N2:N13)/12 -> 9756.3333 | O14: =SUM(O2:O13)/12 -> 8969.25 | ... W14: =SUM(W2:W13)/12 -> 21493.3 | X14: =(SUM(B14:T14))/($B$34-1) -> 7788.4758 | Z14: =MEDIAN(B14:T14) -> 8969.25 | AA14: =MAX(B14:T14) -> 28718.126 | AB14: =MIN(B14:T14) -> 6185.3333
A15: Expenses | B15: =SUM(B8:B13) + 5000*6 -> 69054 | C15: =SUM(C2:C13) -> 74224 | D15: =SUM(D2:D13) -> 79170 | E15: =SUM(E2:E13) -> 82173 | F15: =SUM(F2:F13) -> 81548 | G15: =SUM(G2:G13) -> 89971 | H15: =SUM(H2:H13) -> 82506.566 | I15: =SUM(I2:I13) -> 83029.687 | J15: =SUM(J2:J13) -> 119168.4 | ... W15: =SUM(W2:W13) -> 257919.6 | X15: =(SUM(B15:T15))/($B$34-1) -> 92938.751 | Z15: =MEDIAN(B15:T15) -> 107631 | AA15: =MAX(B15:T15) -> 344617.52 | AB15: =MIN(B15:T15) -> 69054
A16: Non Opex | B16: =FinSnapshot!B91 -> 1514 | C16: =FinSnapshot!C91 -> 1814 | D16: =FinSnapshot!D91 -> 956 | E16: =FinSnapshot!E91 -> 1796 | F16: =FinSnapshot!F91 -> 2018 | G16: =FinSnapshot!G91 -> 2516 | H16: =FinSnapshot!H91 -> 2478 | I16: =FinSnapshot!I91 -> 3852 | ... Q16: =FinSnapshot!Q91 -> 2945 | R16: =FinSnapshot!Q91 -> 2945 | S16: =FinSnapshot!S91 -> 5732 | T16: =FinSnapshot!T91 -> 5732 | U16: =FinSnapshot!U91 -> 5732 | V16: =FinSnapshot!V91 -> 5732 | W16: =FinSnapshot!X91 -> 5732 | X16: =(SUM(B16:T16))/($B$34-1) -> 3092.6667 | Z16: =MEDIAN(B16:T16) -> 3852 | AA16: =MAX(B16:T16) -> 6662 | AB16: =MIN(B16:T16) -> 956
A17: Total Expenses | B17: =B15+B16 -> 70568 | C17: =C15+C16 -> 76038 | D17: =D15+D16 -> 80126 | E17: =E15+E16 -> 83969 | F17: =F15+F16 -> 83566 | G17: =G15+G16 -> 92487 | H17: =H15+H16 -> 84984.566 | I17: =I15+I16 -> 86881.687 | ... W17: =W15+W16 -> 263651.6 | X17: =(SUM(B17:T17))/($B$34-1) -> 96031.417 | Z17: =MEDIAN(B17:T17) -> 113595 | AA17: =MAX(B17:T17) -> 350349.52 | AB17: =MIN(B17:T17) -> 70568
A18: IPM | B18: =FinSnapshot!B109/12 -> 7157.6533 | C18: =FinSnapshot!C109/12 -> 7849.6667 | D18: =FinSnapshot!D109/12 -> 8553.75 | E18: =FinSnapshot!E109/12 -> 8587.1667 | F18: =FinSnapshot!F109/12 -> 10583.583 | G18: =FinSnapshot!G109/12 -> 11583.333 | H18: =FinSnapshot!H109/12 -> 11994.618 | I18: =FinSnapshot!I109/12 -> 12089.167 | ... V18: =FinSnapshot!V109/12 -> 41486.966 | W18: =FinSnapshot!X109/12 -> 84731.63 | X18: =(SUM(B18:T18))/($B$34-1) -> 13449.524 | Z18: =MEDIAN(B18:T18) -> 14836.75 | AA18: =MAX(B18:T18) -> 43349.583 | AB18: =MIN(B18:T18) -> 7157.6533
A19: EPD | B19: =B17/365 -> 193.33699 | C19: =C17/365 -> 208.32329 | D19: =D17/365 -> 219.52329 | E19: =E17/365 -> 230.05205 | F19: =F17/365 -> 228.94795 | G19: =G17/365 -> 253.38904 | H19: =H17/365 -> 232.83443 | I19: =I17/365 -> 238.03202 | ... W19: =W17/365 -> 722.33315 | X19: =(SUM(B19:T19))/($B$34-1) -> 263.09977 | Z19: =MEDIAN(B19:T19) -> 311.21918 | AA19: =MAX(B19:T19) -> 959.86169 | AB19: =MIN(B19:T19) -> 193.33699
A20: IPD | B20: =FinSnapshot!B89/365 -> 239.46805 | C20: =FinSnapshot!C89/365 -> 263.0411 | D20: =FinSnapshot!D89/365 -> 283.83836 | E20: =FinSnapshot!E89/365 -> 287.23836 | F20: =FinSnapshot!F89/365 -> 353.48219 | G20: =FinSnapshot!G89/365 -> 387.71507 | H20: =FinSnapshot!H89/365 -> 401.13266 | I20: =FinSnapshot!I89/365 -> 408.00548 | ... V20: =FinSnapshot!V89/365 -> 1365.7961 | W20: =FinSnapshot!X89/365 -> 2695.1714 | X20: =(SUM(B20:T20))/($B$34-1) -> 428.82818 | Z20: =MEDIAN(B20:T20) -> 461.62405 | AA20: =MAX(B20:T20) -> 1393.6164 | AB20: =MIN(B20:T20) -> 239.46805
A21: EPH | B21: =B19/24 -> 8.0557078 | C21: =C19/24 -> 8.680137 | D21: =D19/24 -> 9.1468037 | E21: =E19/24 -> 9.5855023 | F21: =F19/24 -> 9.5394977 | G21: =G19/24 -> 10.557877 | H21: =H19/24 -> 9.7014345 | I21: =I19/24 -> 9.9180008 | ... W21: =W19/24 -> 30.097215 | X21: =(SUM(B21:T21))/($B$34-1) -> 10.962491 | Z21: =MEDIAN(B21:T21) -> 12.967466 | AA21: =MAX(B21:T21) -> 39.994237 | AB21: =MIN(B21:T21) -> 8.0557078
A22: IPH | B22: =B20/24 -> 9.9778356 | C22: =C20/24 -> 10.960046 | D22: =D20/24 -> 11.826598 | E22: =E20/24 -> 11.968265 | F22: =F20/24 -> 14.728425 | G22: =G20/24 -> 16.154795 | H22: =H20/24 -> 16.713861 | I22: =I20/24 -> 17.000228 | ... W22: =W20/24 -> 112.29881 | X22: =(SUM(B22:T22))/($B$34-1) -> 17.867841 | Z22: =MEDIAN(B22:T22) -> 19.234336 | AA22: =MAX(B22:T22) -> 58.067352 | AB22: =MIN(B22:T22) -> 9.9778356
A23: Net Income | B23: ='Financials & Forecast'!B12 -> 17146.84 | C23: ='Financials & Forecast'!C12 -> 20561 | D23: ='Financials & Forecast'!D12 -> 24430 | E23: ='Financials & Forecast'!E12 -> 22428 | F23: ='Financials & Forecast'!F12 -> 48756 | G23: ='Financials & Forecast'!G12 -> 54104 | H23: ='Financials & Forecast'!H12 -> 53897.854 | I23: ='Financials & Forecast'!I12 -> 68094.313 | ... V23: ='Financials & Forecast'!V12 -> 0 | X23: =(SUM(B23:T23))/($B$34-1) -> 68805.159 | Z23: =MEDIAN(B23:T23) -> 65061.601 | AA23: =MAX(B23:T23) -> 386376.5 | AB23: =MIN(B23:T23) -> 17146.84
A24: % Savings | B24: =B23/FinSnapshot!B60 -> 0.14723646 | C24: =C23/FinSnapshot!C60 -> 0.14833492 | D24: =D23/FinSnapshot!D60 -> 0.16717419 | E24: =E23/FinSnapshot!E60 -> 0.14013997 | F24: =F23/FinSnapshot!F60 -> 0.26554977 | G24: =G23/FinSnapshot!G60 -> 0.27564282 | H24: =H23/FinSnapshot!H60 -> 0.26291123 | I24: =I23/FinSnapshot!I60 -> 0.31878017 | ... V24: =V23/FinSnapshot!V60 -> 0 | W24: =W23/FinSnapshot!X60 -> 0 | X24: =(SUM(B24:T24))/($B$34-1) -> 0.20164054 | Z24: =MEDIAN(B24:T24) -> 0.26291123 | AA24: =MAX(B24:T24) -> 0.4707924 | AB24: =MIN(B24:T24) -> 0.062466287
A25: ExpTaxes:Earn | B25: =(B17+ FinSnapshot!B85)/FinSnapshot!B60 -> 0.85541686 | C25: =(C17+ FinSnapshot!C85)/FinSnapshot!C60 -> 0.85591435 | D25: =(D17+ FinSnapshot!D85)/FinSnapshot!D60 -> 0.83936086 | E25: =(E17+ FinSnapshot!E85)/FinSnapshot!E60 -> 0.86957636 | F25: =(F17+ FinSnapshot!F85)/FinSnapshot!F60 -> 0.75242914 | G25: =(G17+ FinSnapshot!G85)/FinSnapshot!G60 -> 0.7502127 | H25: =(H17+ FinSnapshot!H85)/FinSnapshot!H60 -> 0.7003529 | I25: =(I17+ FinSnapshot!I85)/FinSnapshot!I60 -> 0.70956133 | J25: =(J17+ FinSnapshot!J85)/FinSnapshot!J60 -> 0.81076205 | K25: =K17/FinSnapshot!K60 -> 0.41939537 | L25: =L17/FinSnapshot!L60 -> 0.48297483 | M25: =M17/FinSnapshot!M60 -> 0.50600362 | N25: =N17/FinSnapshot!N60 -> 0.41648184 | O25: =O17/FinSnapshot!O60 -> 0.33156549 | P25: =P17/FinSnapshot!P60 -> 0.32391831 | Q25: =Q17/FinSnapshot!Q60 -> 0.16664372 | R25: =R17/FinSnapshot!R60 -> 0.2935595 | ... V25: =V17/FinSnapshot!V60 -> 0.40345959 | W25: =W17/FinSnapshot!X60 -> 0.2680101 | X25: =(SUM(B25:T25))/($B$34-1) -> 0.45863594 | Z25: =MEDIAN(B25:T25) -> 0.63154305 | AA25: =MAX(B25:T25) -> 0.86957636 | AB25: =MIN(B25:T25) -> 0.16664372
A26: NS/M | B26: =B23/12 -> 1428.9033 | C26: =C23/12 -> 1713.4167 | D26: =D23/12 -> 2035.8333 | E26: =E23/12 -> 1869 | F26: =F23/12 -> 4063 | G26: =IF(YEAR(TODAY())=2007,G23/MONTH(TODAY()),G23/12) -> 4508.6667 | H26: =IF(YEAR(TODAY())=2007,H23/MONTH(TODAY()),H23/12) -> 4491.4878 | I26: =IF(YEAR(TODAY())=2007,I23/MONTH(TODAY()),I23/12) -> 5674.5261 | J26: =IF(YEAR(TODAY())=2007,J23/MONTH(TODAY()),J23/12) -> 4280.1151 | K26: =IF(YEAR(TODAY())=2007,K23/MONTH(TODAY()),K23/12) -> 6491.6404 | L26: =IF(YEAR(TODAY())=2007,L23/MONTH(TODAY()),L23/12) -> 5421.8001 | M26: =IF(YEAR(TODAY())=2013,M23/MONTH(TODAY()),M23/12) -> 5598.9334 | N26: =IF(YEAR(TODAY())=2013,N23/MONTH(TODAY()),N23/12) -> 6547.1667 | O26: =IF(YEAR(TODAY())=2013,O23/MONTH(TODAY()),O23/12) -> 10413.75 | P26: =IF(YEAR(TODAY())=2013,P23/MONTH(TODAY()),P23/12) -> 5560.25 | Q26: =IF(YEAR(TODAY())=2013,Q23/MONTH(TODAY()),Q23/12) -> 32198.042 | R26: =IF(YEAR(TODAY())=2013,R23/MONTH(TODAY()),R23/12) -> 15682.972 | S26: =IF(YEAR(TODAY())=2013,S23/MONTH(TODAY()),S23/12) -> 16743.042 | T26: =IF(YEAR(TODAY())=2013,T23/MONTH(TODAY()),T23/12) -> 2887.7727 | ... W26: =IF(YEAR(TODAY())=2013,W23/MONTH(TODAY()),W23/12) -> 0 | X26: =(SUM(B26:T26))/($B$34-1) -> 5733.7632 | Z26: =MEDIAN(B26:T26) -> 5421.8001 | AA26: =MAX(B26:T26) -> 32198.042 | AB26: =MIN(B26:T26) -> 1428.9033
A27: Gross Inc/M | B27: =FinSnapshot!B64/12 -> 9730.57 | C27: =FinSnapshot!C64/12 -> 11600.083 | D27: =FinSnapshot!D64/12 -> 12257.5 | E27: =FinSnapshot!E64/12 -> 13466.25 | F27: =FinSnapshot!F64/12 -> 15575.417 | G27: =FinSnapshot!G64/12 -> 16779.833 | H27: =FinSnapshot!H64/12 -> 17433 | I27: =FinSnapshot!I64/12 -> 18176.083 | ... V27: =FinSnapshot!V64/12 -> 63530.202 | W27: =FinSnapshot!X64/12 -> 85209.297 | X27: =(SUM(B27:T27))/($B$34-1) -> 21605.338 | Z27: =MEDIAN(B27:T27) -> 20519.583 | AA27: =MAX(B27:T27) -> 76181.5 | AB27: =MIN(B27:T27) -> 9730.57
A28: Pass. Inc/M | B28: =FinSnapshot!B52/12 -> 25.75 | C28: =FinSnapshot!C52/12 -> 49.083333 | D28: =FinSnapshot!D52/12 -> 79.583333 | E28: =FinSnapshot!E52/12 -> 129.58333 | F28: =FinSnapshot!F52/12 -> 275.08333 | G28: =FinSnapshot!G52/12 -> 422.91667 | H28: =FinSnapshot!H52/12 -> -627.58333 | I28: =FinSnapshot!I52/12 -> 504.5 | ... V28: =FinSnapshot!V52/12 -> 421.66667 | W28: =FinSnapshot!X52/12 -> 3231.1667 | X28: =(SUM(B28:T28))/($B$34-1) -> 702.53472 | Z28: =MEDIAN(B28:T28) -> 504.5 | AA28: =MAX(B28:T28) -> 3942.75 | AB28: =MIN(B28:T28) -> -627.58333
A29: %Housing/Gross I
A30: Exp YoY | C30: =(C15-B15)/B15 -> 0.074868943 | D30: =(D15-C15)/C15 -> 0.066636128 | E30: =(E15-D15)/D15 -> 0.037931034 | F30: =(F15-E15)/E15 -> -0.0076059046 | G30: =(G15-F15)/F15 -> 0.10328886 | H30: =(H15-G15)/G15 -> -0.082964886 | I30: =(I15-H15)/H15 -> 0.0063403496 | J30: =(J15-I15)/I15 -> 0.43525049 | ... W30: =(W15-V15)/V15 -> -0.13972007
A31: Gross Inc YoY | C31: =(C27-B27)/B27 -> 0.19212783 | D31: =(D27-C27)/C27 -> 0.056673443 | E31: =(E27-D27)/D27 -> 0.098613094 | F31: =(F27-E27)/E27 -> 0.15662613 | G31: =(G27-F27)/F27 -> 0.077328054 | H31: =(H27-G27)/G27 -> 0.038925695 | I31: =(I27-H27)/H27 -> 0.042625098 | J31: =(J27-I27)/I27 -> 0.090759285 | ... W31: =(W27-V27)/V27 -> 0.34124077
A34: Years | B34: =YEAR(TODAY()) - 2002 + 1 -> 25

Sheet TripCompare
A2: Trip | B2: Santa Barbara | C2: LA | D2: Yosemite | E2: Tahoe | F2: Europe - Rome-Paris-London | G2: Oahu | H2: Death Valley | I2: Folsom, CA | J2: Tahoe2 | K2: Banff, AL, CAN | L2: Costa Rica | M2: Las Vegas | N2: Yellow Stone | O2: Tahoe | P2: Ger-FRA-Swiss | Q2: Japan | R2: Solvang, Santab Barbaba | S2: Denmark-Norway
A3: Year | B3: 2021 | C3: 2021 | D3: 2022 | E3: 2022 | F3: 2022 | G3: 2023 | H3: 2023 | I3: 2023 | J3: 2023 | K3: 2023 | L3: 2023 | M3: 2023 | N3: 2024 | O3: 2024 | P3: 2024 | Q3: 2024 | R3: 2024 | S3: 2025
A4: Dates | B4: Aug 4 - Aug 7 | C4: Dec 21 - Dec 25 | D4: Apr 13 -Apr 16 | E4: Jun 24 - Jun 29 | F4: Aug 7 - Aug 15 | G4: Jan 2- Jan 7 | H4: Feb 22- Feb 24 | I4: May27-May28 | J4: Jun 26- June 30 | K4: Aug 3-7 | L4: Nov 18-Nov 23 | M4: Dec 28-Dec 31 | N4: Jun 8 -Jun 12 | O4: Jul 3 -Jul 6 | P4: JUl 31- Aug 6 | Q4: Nov 24 - Nov 29 | R4: Dec 21 - Dec 24 | S4: July 30- Aug 7
A5: Days | B5: 4 | C5: 5 | D5: 4 | E5: 6 | F5: 9 | G5: 5 | H5: 3 | I5: 2 | J5: 5 | K5: 5 | L5: 6 | M5: 4 | N5: 5 | O5: 4 | P5: 7 | Q5: 5 | R5: 4 | S5: 8
A6: Nights | B6: 3 | C6: 4 | D6: 3 | E6: 5 | F6: 8 | G6: 4 | H6: 2 | I6: 1 | J6: 4 | K6: 4 | L6: 5 | M6: 3 | N6: 4 | O6: 3 | P6: 5 | Q6: 4 | R6: 3 | S6: 7
A7: Airfare | B7: - | C7: - | D7: - | E7: - | F7: =Aug!CE11 -> 4562 | G7: 2415 | H7: - | I7: - | K7: 1054 | L7: =Nov!CI12 -> 4053 | M7: =Dec!CI103 -> 1262 | N7: =Jun!CM16 -> 1385 | O7: 0 | P7: =Aug!CM11 -> 6100 | Q7: 5100 | R7: - | S7: 5800
A8: Transportation | B8: 150 | C8: 325 | D8: 225 | E8: 200 | F8: =Aug!CE23 -> 859 | G8: 125 | H8: =177 -> 177 | I8: 175 | J8: =Jun!CI84 -> 34 | K8: =1036-710 -> 326 | L8: =148 -> 148 | M8: =Dec!CI107 -> 197 | N8: =130 -> 130 | O8: =Jul!CM15 -> 288 | P8: =Aug!CM19 -> 1010 | Q8: 500 | R8: 200 | S8: 544
A9: Car Rentals | B9: - | C9: - | D9: - | E9: - | F9: 0 | G9: 469 | H9: - | I9: 0 | J9: - | K9: 605 | L9: 500 | M9: 0 | N9: 899 | O9: 0 | P9: =Aug!CM21 -> 700 | Q9: 899 | R9: 0 | S9: -
A10: Stays | B10: 495 | C10: 490 | D10: 1000 | E10: 1500 | F10: =Aug!CE15 -> 1441 | G10: 1000 | H10: =204 + 155 -> 359 | I10: 210 | J10: =Jun!CI79 -> 1300 | K10: 905 | L10: =1399 + 150 + 150 -> 1699 | M10: =Dec!CI104 -> 930 | N10: =Jun!CM17 -> 1330 | O10: =Jul!CM11 -> 1119 | P10: =Aug!CM13 -> 1254 | Q10: 1000 | R10: 520 | S10: 1931
A11: Food | B11: 180 | C11: 322 | D11: 271 | E11: 390 | F11: =Aug!CE19 -> 677 | G11: 622 | H11: 34 | I11: 102 | J11: =Jun!CI80 -> 414 | K11: 653 | L11: =Nov!CI15 -> 306 | M11: =Dec!CI106 -> 1008 | N11: =Jun!CM20 -> 548 | O11: =Jul!CM14 -> 478 | P11: =Aug!CM18 -> 732 | Q11: 1200 | R11: 240 | S11: =Aug!CQ17 -> 1194
A12: EET | B12: 50 | C12: 1240 | D12: 35 | E12: 620 | F12: =Aug!CE27 -> 416 | G12: 322 | H12: 30 | I12: 758 | J12: =Jun!CI82 -> 614 | K12: 65 | L12: =Nov!CI17 -> 900 | M12: =Dec!CI105 -> 512 | N12: 35 | O12: =Jul!CM20 -> 596 | P12: =Aug!CM24 -> 1004 | Q12: 1500 | R12: - | S12: =Aug!CQ22 -> 1756
A13: Pet boarding | B13: - | C13: - | D13: - | E13: 85 | F13: =Aug!CE32+Aug!CE31 -> 508 | G13: 294 | H13: 190 | I13: 98 | J13: =Jun!CI83 -> 80 | K13: 390 | L13: 390 | M13: 390 | N13: 450 | O13: =Jul!CM21 -> 450 | P13: =Aug!CM26 -> 311 | Q13: =Aug!CM26 -> 311 | R13: 200 | S13: 450
A14: Total | B14: =SUM(B7:B13) -> 875 | C14: =SUM(C7:C13) -> 2377 | D14: =SUM(D7:D13) -> 1531 | E14: =SUM(E7:E13) -> 2795 | F14: =SUM(F7:F13) -> 8463 | G14: =SUM(G7:G13) -> 5247 | H14: =SUM(H7:H13) -> 790 | I14: =SUM(I7:I13) -> 1343 | ... O14: =SUM(O7:O13) -> 2931 | P14: =SUM(P7:P13)-P9 -> 10411 | Q14: =SUM(Q7:Q13) -> 10510 | R14: =SUM(R7:R13) -> 1160 | S14: =SUM(S7:S13) -> 11675
A15: Price Per Night (PPN) | B15: =B14/7 -> 125 | C15: =C14/7 -> 339.57143 | D15: =D14/7 -> 218.71429 | E15: =E14/7 -> 399.28571 | F15: =F14/F6 -> 1057.875 | G15: =G14/G6 -> 1311.75 | H15: =H14/H6 -> 395 | I15: =I14/I6 -> 1343 | J15: =J14/J6 -> 610.5 | K15: =K14/K6 -> 999.5 | L15: =L14/L6 -> 1599.2 | M15: =M14/M6 -> 1433 | ... S15: =S14/S6 -> 1667.8571
A18: Year | B18: 2021 | C18: 2022 | D18: 2023 | E18: 2024 | CQ18: {=TripCompare!S2:S16} -> Denmark-Norway
A19: Trips | B19: 2 | C19: 3 | D19: 7 | E19: 5 | CQ19: 2025
A20: Days | B20: =B5+C5 -> 9 | C20: =SUM(D5:F5) -> 19 | D20: =SUM(G5:M5) -> 30 | E20: 25 | CQ20: July 30- Aug 7
A21: Nights | B21: =B6+C6 -> 7 | C21: =SUM(D6:F6) -> 16 | D21: =SUM(G6:M6) -> 23 | E21: 19 | CQ21: 8
A22: Airfare | B22: - | C22: =SUM(D7:F7) -> 4562 | D22: =SUM(G7:M7) -> 8784 | E22: =SUM(N7:R7) -> 12585 | CQ22: 7
A23: Transportation | B23: =B8+C8 -> 475 | C23: =SUM(D8:F8) -> 1284 | D23: =SUM(G8:M8) -> 1182 | E23: =SUM(N8:R8) -> 2128 | CQ23: 5800
A24: Car Rentals | B24: - | C24: =SUM(D9:F9) -> 0 | D24: =SUM(G9:M9) -> 1574 | E24: =SUM(N9:R9) -> 2498 | CQ24: 544
A25: Stays | B25: =B10+C10 -> 985 | C25: =SUM(D10:F10) -> 3941 | D25: =SUM(G10:M10) -> 6403 | E25: =SUM(N10:R10) -> 5223 | CQ25: -
A26: Food | B26: =B11+C11 -> 502 | C26: =SUM(D11:F11) -> 1338 | D26: =SUM(G11:M11) -> 3139 | E26: =SUM(N11:R11) -> 3198 | CQ26: 1931
A27: EET | B27: =B12+C12 -> 1290 | C27: =SUM(D12:F12) -> 1071 | D27: =SUM(G12:M12) -> 3201 | E27: =SUM(N12:R12) -> 3135 | CQ27: 1194
A28: Pet boarding | B28: - | C28: =SUM(D13:F13) -> 593 | D28: =SUM(G13:M13) -> 1832 | E28: =SUM(N13:R13) -> 1722 | CQ28: 1756
A29: Total | B29: =B14+C14 -> 3252 | C29: =SUM(D14:F14) -> 12789 | D29: =SUM(G14:M14) -> 26115 | E29: =SUM(N14:R14) -> 29789 | CQ29: 450
